<?xml version="1.0" ?>
<robot xmlns:xacro="http://www.ros.org/wiki/xacro">

    <!-- Upperarm roll: internal fixed attchment point for upper arm -->
    <xacro:macro name="pr2_upper_arm_roll" params="side parent reflect *origin">
        <joint name="${side}_upper_arm_roll_joint" type="revolute">
        <axis xyz="1 0 0" />
        <xacro:insert_block name="origin" />
        <parent link="${parent}" />
        <child link="${side}_upper_arm_roll_link"/>
        <limit lower="${reflect*1.55-2.35}" upper="${reflect*1.55+2.35}" effort="30" velocity="${VELOCITY_LIMIT_SCALE*5.45}" /> <!-- alpha tested velocity and effort limits -->
        <!--safety_controller k_position="100" k_velocity="2" soft_lower_limit="${reflect*1.55-2.35+0.15}" soft_upper_limit="${reflect*1.55+2.35-0.15}" /-->
        <calibration rising="${(reflect*M_PI/2)*cal_r_upper_arm_roll_gearing + cal_r_upper_arm_roll_flag}" />
        <dynamics damping="0.1" />
        </joint>

        <link name="${side}_upper_arm_roll_link">
        <inertial>
            <mass value="0.1" />
            <origin xyz="0.0 0 0" rpy="0 0 0" />
            <inertia  ixx="0.01" ixy="0.00"  ixz="0.00"
                    iyy="0.01" iyz="0.00"
                    izz="0.01" />
        </inertial>
        <visual>
            <origin xyz="0 0 0" rpy="0 0 0" />
            <geometry>
            <mesh filename="package://pr2_tc_description/meshes/shoulder_v0/upper_arm_roll.stl"  />
            </geometry>
            <material name="RollLinks" />
        </visual>
        <collision>
            <origin xyz="0 0 0" rpy="0 0 0" />
            <geometry>
            <mesh filename="package://pr2_tc_description/meshes/shoulder_v0/upper_arm_roll_L.stl"  />
            </geometry>
        </collision>
        </link>
    </xacro:macro>

    <xacro:macro name="pr2_upper_arm" params="side parent reflect">
        <joint name="${side}_upper_arm_joint" type="fixed">
        <origin xyz="0 0 0" rpy="0 0 0" />
        <parent link="${parent}"/>
        <child link="${side}_upper_arm_link"/>
        </joint>
        <link name="${side}_upper_arm_link">
        <inertial>
            <!-- NOTE:reflect==-1 for right side, reflect==1 for the left side -->
            <mass value="6.01769" />
            <origin xyz="${0.5*((reflect+1)*ual_xyz1+(1-reflect)*uar_xyz1)} ${0.5*((reflect+1)*ual_xyz2+(1-reflect)*uar_xyz2)} ${0.5*((reflect+1)*ual_xyz3+(1-reflect)*uar_xyz3)}" />
            <inertia  ixx="${0.5*((reflect+1)*ual_ixx+(1-reflect)*uar_ixx)}"
                    ixy="${0.5*((reflect+1)*ual_ixy+(1-reflect)*uar_ixy)}"
                    ixz="${0.5*((reflect+1)*ual_ixz+(1-reflect)*uar_ixz)}"
                    iyy="${0.5*((reflect+1)*ual_iyy+(1-reflect)*uar_iyy)}"
                    iyz="${0.5*((reflect+1)*ual_iyz+(1-reflect)*uar_iyz)}"
                    izz="${0.5*((reflect+1)*ual_izz+(1-reflect)*uar_izz)}" />
        </inertial>
        <visual>
            <origin xyz="0 0 0" rpy="0 0 0" />
            <geometry>
            <mesh filename="package://pr2_tc_description/meshes/upper_arm_v0/upper_arm.dae"  />
            </geometry>
            <material name="Green" />
        </visual>
        <collision>
            <origin xyz="0 0 0" rpy="0 0 0" />
            <geometry>
            <mesh filename="package://pr2_tc_description/meshes/upper_arm_v0/upper_arm.stl"  />
            </geometry>
        </collision>
        </link>
        <!-- Elbow flex, FA roll macros -->
        <xacro:pr2_forearm_roll side="${side}" parent="${side}_elbow_flex_link" reflect="${reflect}" />
        <xacro:pr2_elbow_flex side="${side}" parent="${side}_upper_arm_link" reflect="${reflect}" />
    </xacro:macro>

    <xacro:macro name="pr2_elbow_flex" params="side parent reflect">
        <!-- Elbow flex -->
        <joint name="${side}_elbow_flex_joint" type="revolute">
        <axis xyz="0 1 0" />
        <!-- Note: Overtravel limits are 140, -7 degrees instead of 133, 0 -->
        <limit lower="-2.3213" upper="0.00" effort="30" velocity="${VELOCITY_LIMIT_SCALE*5.5}" /> <!-- alpha tested velocity and effort limits -->
        <!--safety_controller k_position="100" k_velocity="3" soft_lower_limit="${-2.3213+0.2}" soft_upper_limit="${0.00-0.15}" /-->
        <calibration falling="${-1.1606 + cal_r_elbow_flex_flag}"/>
        <dynamics damping="1.0" />
        <origin xyz="0.4 0 0" rpy="0 0 0" />
        <parent link="${parent}"/>
        <child link="${side}_elbow_flex_link"/>
        </joint>
        <link name="${side}_elbow_flex_link">
        <inertial>
            <mass value="1.90327" />
            <origin xyz="0.01014 0.00032 -0.01211" />
            <inertia  ixx="0.00346541989" ixy="0.00004066825"  ixz="0.00043171614"
                    iyy="0.00441606455"  iyz="-0.00003968914"
                    izz="0.00359156824" />
        </inertial>

        <visual>
            <origin xyz="0 0 0" rpy="0 0 0" />
            <geometry>
            <mesh filename="package://pr2_tc_description/meshes/upper_arm_v0/elbow_flex.dae"  />
            </geometry>

            <material name="Grey" />
        </visual>

        <collision>
            <origin xyz="0 0 0" rpy="0 0 0" />
            <geometry>
            <mesh filename="package://pr2_tc_description/meshes/upper_arm_v0/elbow_flex.stl"  />
            </geometry>
        </collision>
        </link>
    </xacro:macro>

    <!-- FA roll joint only -->
    <xacro:macro name="pr2_forearm_roll" params="side parent reflect">
        <!-- forearm_roll_link is a fictitious link internal to elbow_flex_link, provides an attachment point for the actual forearm -->
        <joint name="${side}_forearm_roll_joint" type="continuous">
        <axis xyz="1 0 0" />
        <limit effort="30" velocity="${VELOCITY_LIMIT_SCALE*6}" /> <!-- alpha tested velocity and effort limits -->
        <safety_controller k_velocity="1" />
        <calibration rising="${0.0 + cal_r_forearm_roll_flag}" />
        <dynamics damping="0.1" />
        <origin xyz="0 0 0" rpy="0 0 0" />
        <parent link="${parent}"/>
        <child link="${side}_forearm_roll_link"/>
        </joint>

        <link name="${side}_forearm_roll_link">
        <inertial>
            <mass value="0.1" />
            <origin xyz="0 0 0" />
            <inertia  ixx="0.01" ixy="0.00"  ixz="0.00"
                    iyy="0.01" iyz="0.00"
                    izz="0.01" />
        </inertial>
        <visual>
            <origin xyz="0 0 0" rpy="0 0 0" />
            <geometry>
            <mesh filename="package://pr2_tc_description/meshes/upper_arm_v0/forearm_roll.stl"  />
            </geometry>

            <material name="RollLinks" />
        </visual>
        <!-- TODO: collision tag should be optional -->
        <collision>
            <origin xyz="0 0 0" rpy="0 0 0" />
            <geometry>
            <mesh filename="package://pr2_tc_description/meshes/upper_arm_v0/forearm_roll_L.stl"  />
            </geometry>
        </collision>
        </link>
    </xacro:macro>

    <xacro:macro name="pr2_forearm" params="side parent reflect *origin">
        <joint name="${side}_forearm_joint" type="fixed">
        <xacro:insert_block name="origin" /> <!-- transform from parent link to this joint frame -->
        <parent link="${parent}"/>
        <child link="${side}_forearm_link"/>
        </joint>

        <link name="${side}_forearm_link">
        <inertial>
            <mass value="2.57968" />
            <origin xyz="0.18791 -0.00017 -0.00912" />
            <inertia ixx="0.00364857222" ixy="0.00005215877" ixz="0.00071534842"
                    iyy="0.01507736897" iyz="-0.00001310770"
                    izz="0.01659310749" />
        </inertial>
        <visual>
            <origin xyz="0 0 0" rpy="0 0 0" />
            <geometry>
            <mesh filename="package://pr2_tc_description/meshes/forearm_v0/forearm.dae" />
        </geometry>
            <material name="Grey" />
        </visual>
        <collision>
            <origin xyz="0 0 0" rpy="0 0 0" />
            <geometry>
            <mesh filename="package://pr2_tc_description/meshes/forearm_v0/forearm.stl" />
            </geometry>
        </collision>
        </link>

        <!-- Wrist flex -->
        <joint name="${side}_wrist_flex_joint" type="revolute">
        <axis xyz="0 1 0" />
        <limit upper="0.0" lower="-2.18" effort="10" velocity="${VELOCITY_LIMIT_SCALE*5.13}" /> <!-- alpha tested velocity and effort limits -->
        <!--safety_controller k_position="20" k_velocity="4" soft_upper_limit="${0.0 - 0.10}" soft_lower_limit="${-2.18 + 0.18}" /-->
        <dynamics damping="0.1" />
        <calibration falling="${-0.5410521 + cal_r_wrist_flex_flag}" />
        <origin xyz="0.321 0 0" rpy="0 0 0" />
        <parent link="${side}_forearm_link"/>
        <child link="${side}_wrist_flex_link"/>
        </joint>

        <link name="${side}_wrist_flex_link">
        <inertial>
            <mass value="0.61402" />
            <origin xyz="-0.00157 0.0 -0.00075" />
            <inertia ixx="0.00065165722" ixy="0.00000028864" ixz="0.00000303477"
                    iyy="0.00019824443" iyz="-0.00000022645"
                    izz="0.00064450498" />
        </inertial>
        <visual>
            <origin xyz="0 0 0" rpy="0 0 0" />
            <geometry>
            <mesh filename="package://pr2_tc_description/meshes/forearm_v0/wrist_flex.dae" />
            </geometry>
            <material name="Grey" />
        </visual>
        <collision>
            <origin xyz="0 0 0" rpy="0 0 0" />
            <geometry>
            <mesh filename="package://pr2_tc_description/meshes/forearm_v0/wrist_flex.stl" />
            </geometry>
        </collision>
        </link>

        <!-- Wrist roll -->
        <joint name="${side}_wrist_roll_joint" type="continuous">
        <axis xyz="1 0 0" />
        <limit effort="10" velocity="${VELOCITY_LIMIT_SCALE*6}" /> <!-- alpha tested velocity and effort limits -->
        <safety_controller k_velocity="2" />
        <dynamics damping="0.1" />
        <calibration rising="${-M_PI / 2 + cal_r_wrist_roll_flag}" />
        <origin xyz="0 0 0" rpy="0 0 0" />
        <parent link="${side}_wrist_flex_link"/>
        <child link="${side}_wrist_roll_link"/>
        </joint>
        <link name="${side}_wrist_roll_link">
        <inertial>
            <mass value="0.1" />
            <origin xyz="0 0 0" />
            <inertia ixx="0.01" ixy="0" ixz="0"
                    iyy="0.01" iyz="0"
                    izz="0.01" />
        </inertial>
        <visual>
            <origin xyz="0 0 0" rpy="0 0 0" />
            <geometry>
            <mesh filename="package://pr2_tc_description/meshes/forearm_v0/wrist_roll.stl" />
            </geometry>
            <material name="RollLinks" />
        </visual>
        <collision>
            <origin xyz="0 0 0" rpy="0 0 0" />
            <geometry>
            <mesh filename="package://pr2_tc_description/meshes/forearm_v0/wrist_roll_L.stl" />
            </geometry>
        </collision>
        </link>
    </xacro:macro>



</robot>